Workbook

Sheet Datos
A2: PARTE 1: DETERMINACIÓN DE D | U2: Incertidumbre | V2: 0,1 g
U3: Masa cilindro 1 | V3: 238,3 g | W3: h = 3,32 cm | X3: d = 3,53 cm
A4: PERIODO TRAS CINCO OSCILACIONES (seg) | B4: Medias | C4: Periodo | D4: Desviación muestral s | E4: u_(A) = s/(3)^1/2 | F4: u (tn) | G4: u (T) = u(tn) / n | H4: u (T^2) = 2 T u(T) | I4: Posición simétrica de los cilindros | J4: Medida (cm) | K4: T^2 | L4: R^2 | M4: R^2 (m^2) | U4: Masa cilindro 2 | V4: 238,1 g | W4: h = 3,32 cm | X4: d = 3,53 cm
A5: 37.18 | I5: 1 | J5: 30 | U5: Masa barra | V5: 131,1 g
A6: 37.5 | J6: 30 | U6: Masa esfera | V6: 948,1 g | X6: P = 46,0 cm (perímetro, cinta métrica) | Y6: D = P/π = 14,64 cm
A7: 37.66 | B7: =(A5+A6+A7)/3 -> 37.446667 | C7: =B7/5 -> 7.4893333 | D7: =STDEV(A5:A7) -> 0.24440404 | E7: =D7/SQRT(3) -> 0.14110674 | F7: =SQRT(E7^2+0.01^2/12) -> 0.14113626 | G7: =F7/5 -> 0.028227252 | H7: =2*C7*G7 -> 0.4228066 | J7: 30 | K7: =C7^2 -> 56.090114 | L7: =J7^2 -> 900 | M7: =L7/10000 -> 0.09 | U7: Masa cilindro hueco | V7: 399,5 g | W7: h = 9,05 cm | X7: d = 9,03 cm
A8: 31.87 | I8: 2 | J8: 25 | U8: Masa cilindro macizo | V8: 340,8 g | W8: h = 9,09 cm | X8: d = 8,94 cm
A9: 31.87 | J9: 25 | U9: Masa soporte (cilindro) | V9: 134,7 g | X9: d 9,99 cm
A10: 32.09 | B10: =(A8+A9+A10)/3 -> 31.943333 | C10: =B10/5 -> 6.3886667 | D10: =STDEV(A8:A10) -> 0.12701706 | E10: =D10/SQRT(3) -> 0.073333333 | F10: =SQRT(E10^2+0.01^2/12) -> 0.07339013 | G10: =F10/5 -> 0.014678026 | H10: =2*C10*G10 -> 0.18754603 | J10: 25 | K10: =C10^2 -> 40.815062 | L10: =J10^2 -> 625 | M10: =L10/10000 -> 0.0625 | U10: Longitud barra | V10: 60,0 cm
A11: 26.18 | I11: 3 | J11: 20 | U11: Resolución pie de rey | V11: 0,1 mm
A12: 26.35 | J12: 20
A13: 25.97 | B13: =(A11+A12+A13)/3 -> 26.166667 | C13: =B13/5 -> 5.2333333 | D13: =STDEV(A11:A13) -> 0.19035055 | E13: =D13/SQRT(3) -> 0.10989894 | F13: =SQRT(E13^2+0.01^2/12) -> 0.10993685 | G13: =F13/5 -> 0.02198737 | H13: =2*C13*G13 -> 0.23013447 | J13: 20 | K13: =C13^2 -> 27.387778 | L13: =J13^2 -> 400 | M13: =L13/10000 -> 0.04
A14: 20.78 | I14: 4 | J14: 15
A15: 20.85 | J15: 15
A16: 20.87 | B16: =(A14+A15+A16)/3 -> 20.833333 | C16: =B16/5 -> 4.1666667 | D16: =STDEV(A14:A16) -> 0.047258156 | E16: =D16/SQRT(3) -> 0.027284509 | F16: =SQRT(E16^2+0.01^2/12) -> 0.027436796 | G16: =F16/5 -> 0.0054873592 | H16: =2*C16*G16 -> 0.045727993 | J16: 15 | K16: =C16^2 -> 17.361111 | L16: =J16^2 -> 225 | M16: =L16/10000 -> 0.0225
A17: 16.28 | I17: 5 | J17: 10
A18: 16.37 | J18: 10
A19: 16.09 | B19: =(A17+A18+A19)/3 -> 16.246667 | C19: =B19/5 -> 3.2493333 | D19: =STDEV(A17:A19) -> 0.14294521 | E19: =D19/SQRT(3) -> 0.082529456 | F19: =SQRT(E19^2+0.01^2/12) -> 0.082579928 | G19: =F19/5 -> 0.016515986 | H19: =2*C19*G19 -> 0.10733188 | J19: 10 | K19: =C19^2 -> 10.558167 | L19: =J19^2 -> 100 | M19: =L19/10000 -> 0.01
A20: 12.87 | I20: 6 | J20: 5
A21: 12.53 | J21: 5
A22: 12.32 | B22: =(A20+A21+A22)/3 -> 12.573333 | C22: =B22/5 -> 2.5146667 | D22: =STDEV(A20:A22) -> 0.27754879 | E22: =D22/SQRT(3) -> 0.16024287 | F22: =SQRT(E22^2+0.01^2/12) -> 0.16026887 | G22: =F22/5 -> 0.032053774 | H22: =2*C22*G22 -> 0.16120912 | J22: 5 | K22: =C22^2 -> 6.3235484 | L22: =J22^2 -> 25 | M22: =L22/10000 -> 0.0025
A26: PARTE 2: PERIODO DE OSCILACIÓN DEL DISCO PERFORADO (ETIQUETA HACIA FUERA)
A28: PERIODO TRAS CINCO OSCILACIONES (seg) | B28: Medias | C28: Periodo | D28: Desviación muestral s | E28: u_(A) = s/(3)^1/2 | F28: u (tn) | G28: u (T) = u(tn) / n | H28: u (T^2) = 2 T u(T) | I28: Posición (cm) | K28: T^2 | L28: r^2 (cm^2) | M28: r^2 (m^2)
A29: 20.41 | I29: 0 (posición central)
A30: 20.85
A31: 20.53 | B31: =(A29+A30+A31)/3 -> 20.596667 | C31: =B31/5 -> 4.1193333 | D31: =STDEV(A29:A31) -> 0.22744963 | E31: =D31/SQRT(3) -> 0.1313181 | F31: =SQRT(E31^2+0.01^2/12) -> 0.13134983 | G31: =F31/5 -> 0.026269966 | H31: =2*C31*G31 -> 0.21642949 | K31: =C31^2 -> 16.968907 | L31: 0 | M31: =L31/10000 -> 0
A32: 20 | I32: 4 (posición 1 hacia nosotros)
A33: 19.94
A34: 19.78 | B34: =(A32+A33+A34)/3 -> 19.906667 | C34: =B34/5 -> 3.9813333 | D34: =STDEV(A32:A34) -> 0.11372481 | E34: =D34/SQRT(3) -> 0.065659052 | F34: =SQRT(E34^2+0.01^2/12) -> 0.065722481 | G34: =F34/5 -> 0.013144496 | H34: =2*C34*G34 -> 0.10466524 | K34: =C34^2 -> 15.851015 | L34: 16 | M34: =L34/10000 -> 0.0016
A35: 20.41 | I35: 8 (posición 2 hacia nosotros)
A36: 20.91
A37: 21.06 | B37: =(A35+A36+A37)/3 -> 20.793333 | C37: =B37/5 -> 4.1586667 | D37: =STDEV(A35:A37) -> 0.34034296 | E37: =D37/SQRT(3) -> 0.1964971 | F37: =SQRT(E37^2+0.01^2/12) -> 0.19651831 | G37: =F37/5 -> 0.039303661 | H37: =2*C37*G37 -> 0.32690165 | K37: =C37^2 -> 17.294508 | L37: 64 | M37: =L37/10000 -> 0.0064
A38: 22.5 | I38: 12 (posición 3 hacia nosotros)
A39: 22.22
A40: 22.94 | B40: =(A38+A39+A40)/3 -> 22.553333 | C40: =B40/5 -> 4.5106667 | D40: =STDEV(A38:A40) -> 0.36295087 | E40: =D40/SQRT(3) -> 0.20954978 | F40: =SQRT(E40^2+0.01^2/12) -> 0.20956966 | G40: =F40/5 -> 0.041913933 | H40: =2*C40*G40 -> 0.37811956 | K40: =C40^2 -> 20.346114 | L40: 144 | M40: =L40/10000 -> 0.0144
A41: 25.44 | I41: 16 (posición 4 hacia nosotros)
A42: 24.82
A43: 25.28 | B43: =(A41+A42+A43)/3 -> 25.18 | C43: =B43/5 -> 5.036 | D43: =STDEV(A41:A43) -> 0.32186954 | E43: =D43/SQRT(3) -> 0.18583146 | F43: =SQRT(E43^2+0.01^2/12) -> 0.18585389 | G43: =F43/5 -> 0.037170777 | H43: =2*C43*G43 -> 0.37438407 | K43: =C43^2 -> 25.361296 | L43: 256 | M43: =L43/10000 -> 0.0256
A44: (*** Invertimos la placa ***)
A45: 19.91 | I45: - 2 (posición central)
...

Sheet Resultados
B1: Práctica 1 · Momento de inercia. Teorema de Steiner — resultados
B2: Unidades SI. Incertidumbres típicas u; ampliadas U = t·u al 95 %. Ajustes por mínimos cuadrados ordinarios (sin ponderar).
B4: PARTE 1 · Constante de torsión D
B5: R^2 (m^2) | C5: T^2 (s^2) | D5: u(T^2) (s^2)
B6: =Datos!M7 -> 0.09 | C6: =Datos!K7 -> 56.090114 | D6: =Datos!H7 -> 0.4228066
B7: =Datos!M10 -> 0.0625 | C7: =Datos!K10 -> 40.815062 | D7: =Datos!H10 -> 0.18754603
B8: =Datos!M13 -> 0.04 | C8: =Datos!K13 -> 27.387778 | D8: =Datos!H13 -> 0.23013447
B9: =Datos!M16 -> 0.0225 | C9: =Datos!K16 -> 17.361111 | D9: =Datos!H16 -> 0.045727993
B10: =Datos!M19 -> 0.01 | C10: =Datos!K19 -> 10.558167 | D10: =Datos!H19 -> 0.10733188
B11: =Datos!M22 -> 0.0025 | C11: =Datos!K22 -> 6.3235484 | D11: =Datos!H22 -> 0.16120912
B13: Pendiente a (s^2/m^2) | C13: =SLOPE(C6:C11,B6:B11) -> 571.35644
B14: u(a) | C14: =STEYX(C6:C11,B6:B11)/SQRT(DEVSQ(B6:B11)) -> 3.4683628
B15: Ordenada b (s^2) | C15: =INTERCEPT(C6:C11,B6:B11) -> 4.7586983 | E15: u(b) | F15: =C14*SQRT(SUMSQ(B6:B11)/COUNT(B6:B11)) -> 0.16884166
B16: D = 8π² m_c / a (N m/rad) | C16: =8*PI()^2*C21/C13 -> 0.032917312 | D16: m_c = media de los dos cilindros
B17: u(D) | C17: =C16*SQRT((C22/C21)^2+(C14/C13)^2) -> 0.00020029857
B18: t(95 %, ν = N−2 = 4) | C18: =TINV(0.05,COUNT(B6:B11)-2) -> 2.7764451
B19: U(D) = t·u(D) | C19: =C18*C17 -> 0.00055611799
B20: Coeficiente de correlación r | C20: =CORREL(B6:B11,C6:C11) -> 0.99992631
B21: m_c media (kg) | C21: =(0.2383+0.2381)/2 -> 0.2382
B22: u(m_c) (kg) | C22: =0.0001 -> 0.0001
B24: I_b = m_b L^2 / 12 (kg m^2) | C24: =0.1311*0.6^2/12 -> 0.003933
B25: u(I_b) | C25: =SQRT((0.6^2/12*0.0001)^2+(0.1311*0.6/6*0.001)^2) -> 1.344887e-05 | D25: u(m_b) = 0,1 g; u(L) = 1 mm
B26: I_c (m_c media) = m_c (d²/16 + h²/12) | C26: =C21*(0.0353^2/16+0.0332^2/12) -> 4.0430629e-05
B27: u(I_c) | C27: =SQRT(((0.0353^2/16+0.0332^2/12)*C22)^2+(C21*0.0353/8*0.0001)^2+(C21*0.0332/6*0.0001)^2) -> 1.694332e-07 | D27: u(d) = u(h) = 0,1 mm (pie de rey)
B28: Ordenada teórica 4π²(I_b + 2 I_c)/D (s^2) | C28: =4*PI()^2*(C24+2*C26)/C16 -> 4.8139074
B30: PARTE 2 · Teorema de Steiner (disco perforado)
B31: r^2 (m^2) serie 1 | C31: T^2 serie 1 | D31: r^2 (m^2) serie 2 | E31: T^2 serie 2
B32: =Datos!M31 -> 0 | C32: =Datos!K31 -> 16.968907 | D32: =Datos!M47 -> 0.0004 | E32: =Datos!K47 -> 16.117548
B33: =Datos!M34 -> 0.0016 | C33: =Datos!K34 -> 15.851015 | D33: =Datos!M50 -> 0.0016 | E33: =Datos!K50 -> 15.355948
B34: =Datos!M37 -> 0.0064 | C34: =Datos!K37 -> 17.294508 | D34: =Datos!M53 -> 0.0064 | E34: =Datos!K53 -> 17.183788
B35: =Datos!M40 -> 0.0144 | C35: =Datos!K40 -> 20.346114 | D35: =Datos!M56 -> 0.0144 | E35: =Datos!K56 -> 19.102727
B36: =Datos!M43 -> 0.0256 | C36: =Datos!K43 -> 25.361296 | D36: =Datos!M59 -> 0.0256 | E36: =Datos!K59 -> 23.104044
C38: Serie 1 (r ≥ 0) | E38: Serie 2 (r < 0)
B39: Pendiente a (s^2/m^2) | C39: =SLOPE(C32:C36,B32:B36) -> 355.58106 | E39: =SLOPE(E32:E36,D32:D36) -> 292.24715
B40: u(a) | C40: =STEYX(C32:C36,B32:B36)/SQRT(DEVSQ(B32:B36)) -> 45.550636 | E40: =STEYX(E32:E36,D32:D36)/SQRT(DEVSQ(D32:D36)) -> 26.456285
B41: Ordenada b (s^2) | C41: =INTERCEPT(C32:C36,B32:B36) -> 15.75079 | E41: =INTERCEPT(E32:E36,D32:D36) -> 15.343859
B42: u(b) | C42: =C40*SQRT(SUMSQ(B32:B36)/COUNT(B32:B36)) -> 0.61324083 | E42: =E40*SQRT(SUMSQ(D32:D36)/COUNT(D32:D36)) -> 0.35620812
B43: Coeficiente de correlación r | C43: =CORREL(B32:B36,C32:C36) -> 0.97625794 | E43: =CORREL(D32:D36,E32:E36) -> 0.98792939
B44: t(95 %, ν = 3) | C44: =TINV(0.05,COUNT(B32:B36)-2) -> 3.1824463 | E44: =TINV(0.05,COUNT(D32:D36)-2) -> 3.1824463
B45: U(a) | C45: =C44*C40 -> 144.96245 | E45: =E44*E40 -> 84.195708
...
